Workbook

Sheet Sheet1
A1: invoice_id | B1: invoice_date | C1: invoice_pono | D1: invoice_podate | E1: customer_phone | F1: customer_name | G1: customer_gst | H1: customer_address | I1: customer_email | J1: customer_pincode | K1: vehicle_model | L1: vehicle_make | M1: vehicle_license_plate_no | N1: vehicle_external_bikeid | O1: vehicle_registration_no | P1: vehicle_year_of_manufacture | Q1: vehicle_fuel_type | R1: vehicle_transmission_type | S1: vehicle_engine_no | T1: vehicle_chassis_no | U1: vehicle_vin_no | V1: vehicle_color | W1: vehicle_reg_state | X1: vehicle_reg_exp
A2: F0116-C3678 | B2: =VLOOKUP(A2,Sheet2!$A$2:$R$3432,2,0) -> 2025-01-16 19:45:21 | C2: - | D2: - | E2: =VLOOKUP(A2,Sheet2!$A$2:$R$3432,4,0) -> 7887425646 | F2: =VLOOKUP(A2,Sheet2!$A$2:$R$3432,3,0) -> Avinash Jadhav | G2: - | H2: - | I2: - | J2: - | K2: =VLOOKUP(A2,Sheet2!$A$2:$R$3432,6,0) -> Yamaha Gladiator G5 | L2: - | M2: =VLOOKUP(A2,Sheet2!$A$2:$R$3432,5,0) -> MH28AD2026 | N2: - | O2: - | P2: - | Q2: - | R2: - | S2: =VLOOKUP(A2,Sheet2!$A$2:$R$3432,18,0) -> 35B404594 | T2: =VLOOKUP(A2,Sheet2!$A$2:$R$3432,17,0) -> ME1358044C2046624
A3: F0116-C3680 | B3: =VLOOKUP(A3,Sheet2!$A$2:$R$3432,2,0) -> 2025-01-16 19:56:55 | C3: - | D3: - | E3: =VLOOKUP(A3,Sheet2!$A$2:$R$3432,4,0) -> 9762184184 | F3: =VLOOKUP(A3,Sheet2!$A$2:$R$3432,3,0) -> AMOL CHITTE | G3: - | H3: - | I3: - | J3: - | K3: =VLOOKUP(A3,Sheet2!$A$2:$R$3432,6,0) -> Yamaha FZ 1 | L3: - | M3: =VLOOKUP(A3,Sheet2!$A$2:$R$3432,5,0) -> MH28AF8597 | N3: - | O3: - | P3: - | Q3: - | R3: - | S3: =VLOOKUP(A3,Sheet2!$A$2:$R$3432,18,0) | T3: =VLOOKUP(A3,Sheet2!$A$2:$R$3432,17,0)
A4: F0116-C3672 | B4: =VLOOKUP(A4,Sheet2!$A$2:$R$3432,2,0) -> 2025-01-16 19:53:58 | C4: - | D4: - | E4: =VLOOKUP(A4,Sheet2!$A$2:$R$3432,4,0) -> 9049536462 | F4: =VLOOKUP(A4,Sheet2!$A$2:$R$3432,3,0) -> MANOJ CHAUDHARI | G4: - | H4: - | I4: - | J4: - | K4: =VLOOKUP(A4,Sheet2!$A$2:$R$3432,6,0) -> Honda Activa 125 | L4: - | M4: =VLOOKUP(A4,Sheet2!$A$2:$R$3432,5,0) -> MH12TW0951 | N4: - | O4: - | P4: - | Q4: - | R4: - | S4: =VLOOKUP(A4,Sheet2!$A$2:$R$3432,18,0) -> JK13EG1004280 | T4: =VLOOKUP(A4,Sheet2!$A$2:$R$3432,17,0) -> ME4JK133LMG001221
A5: F0115-C3666 | B5: =VLOOKUP(A5,Sheet2!$A$2:$R$3432,2,0) -> 2025-01-16 19:58:37 | C5: - | D5: - | E5: =VLOOKUP(A5,Sheet2!$A$2:$R$3432,4,0) -> 9049536462 | F5: =VLOOKUP(A5,Sheet2!$A$2:$R$3432,3,0) -> Manoj | G5: - | H5: - | I5: - | J5: - | K5: =VLOOKUP(A5,Sheet2!$A$2:$R$3432,6,0) -> Honda Activa | L5: - | M5: =VLOOKUP(A5,Sheet2!$A$2:$R$3432,5,0) -> MH14ES3499 | N5: - | O5: - | P5: - | Q5: - | R5: - | S5: =VLOOKUP(A5,Sheet2!$A$2:$R$3432,18,0) | T5: =VLOOKUP(A5,Sheet2!$A$2:$R$3432,17,0) -> ME4JF502LE8313692
A6: F0113-C3659 | B6: =VLOOKUP(A6,Sheet2!$A$2:$R$3432,2,0) -> 2025-01-16 19:59:01 | C6: - | D6: - | E6: =VLOOKUP(A6,Sheet2!$A$2:$R$3432,4,0) -> 9049536462 | F6: =VLOOKUP(A6,Sheet2!$A$2:$R$3432,3,0) -> Manoj | G6: - | H6: - | I6: - | J6: - | K6: =VLOOKUP(A6,Sheet2!$A$2:$R$3432,6,0) -> Honda Activa | L6: - | M6: =VLOOKUP(A6,Sheet2!$A$2:$R$3432,5,0) -> MH14GB8855 | N6: - | O6: - | P6: - | Q6: - | R6: - | S6: =VLOOKUP(A6,Sheet2!$A$2:$R$3432,18,0) -> JF50U3017142 | T6: =VLOOKUP(A6,Sheet2!$A$2:$R$3432,17,0) -> ME4JF507BHU017099
A7: F0116-C3682 | B7: =VLOOKUP(A7,Sheet2!$A$2:$R$3432,2,0) -> 2025-01-16 20:36:29 | C7: - | D7: - | E7: =VLOOKUP(A7,Sheet2!$A$2:$R$3432,4,0) -> 9503093379 | F7: =VLOOKUP(A7,Sheet2!$A$2:$R$3432,3,0) -> VIPUL GUNJAL | G7: - | H7: - | I7: - | J7: - | K7: =VLOOKUP(A7,Sheet2!$A$2:$R$3432,6,0) -> TVS Scooty PEP | L7: - | M7: =VLOOKUP(A7,Sheet2!$A$2:$R$3432,5,0) -> MH14BV6616 | N7: - | O7: - | P7: - | Q7: - | R7: - | S7: =VLOOKUP(A7,Sheet2!$A$2:$R$3432,18,0) | T7: =VLOOKUP(A7,Sheet2!$A$2:$R$3432,17,0)
A8: F0116-C3675 | B8: =VLOOKUP(A8,Sheet2!$A$2:$R$3432,2,0) -> 2025-01-16 20:37:46 | C8: - | D8: - | E8: =VLOOKUP(A8,Sheet2!$A$2:$R$3432,4,0) -> 9146437954 | F8: =VLOOKUP(A8,Sheet2!$A$2:$R$3432,3,0) -> Archana Shingare | G8: - | H8: - | I8: - | J8: - | K8: =VLOOKUP(A8,Sheet2!$A$2:$R$3432,6,0) -> TVS Scooty PEP Plus | L8: - | M8: =VLOOKUP(A8,Sheet2!$A$2:$R$3432,5,0) -> MH14GV7627 | N8: - | O8: - | P8: - | Q8: - | R8: - | S8: =VLOOKUP(A8,Sheet2!$A$2:$R$3432,18,0) -> AG3AJ2937060 | T8: =VLOOKUP(A8,Sheet2!$A$2:$R$3432,17,0) -> MD626FG38J2AG0938
A9: F0116-C3676 | B9: =VLOOKUP(A9,Sheet2!$A$2:$R$3432,2,0) -> 2025-01-16 20:37:08 | C9: - | D9: - | E9: =VLOOKUP(A9,Sheet2!$A$2:$R$3432,4,0) -> 7385942438 | F9: =VLOOKUP(A9,Sheet2!$A$2:$R$3432,3,0) -> Anchal | G9: - | H9: - | I9: - | J9: - | K9: =VLOOKUP(A9,Sheet2!$A$2:$R$3432,6,0) -> Honda Activa 110 | L9: - | M9: =VLOOKUP(A9,Sheet2!$A$2:$R$3432,5,0) -> MH27AZ5188 | N9: - | O9: - | P9: - | Q9: - | R9: - | S9: =VLOOKUP(A9,Sheet2!$A$2:$R$3432,18,0) -> JF50E82558366 | T9: =VLOOKUP(A9,Sheet2!$A$2:$R$3432,17,0) -> ME4JF301KD8559676
A10: F0116-C3673 | B10: =VLOOKUP(A10,Sheet2!$A$2:$R$3432,2,0) -> 2025-01-16 20:38:01 | C10: - | D10: - | E10: =VLOOKUP(A10,Sheet2!$A$2:$R$3432,4,0) -> 9673758691 | F10: =VLOOKUP(A10,Sheet2!$A$2:$R$3432,3,0) -> RUSHIKESH SHELKE | G10: - | H10: - | I10: - | J10: - | K10: =VLOOKUP(A10,Sheet2!$A$2:$R$3432,6,0) -> Yamaha FZ No Data | L10: - | M10: =VLOOKUP(A10,Sheet2!$A$2:$R$3432,5,0) -> MH12RB1925 | N10: - | O10: - | P10: - | Q10: - | R10: - | S10: =VLOOKUP(A10,Sheet2!$A$2:$R$3432,18,0) -> G3H7E0071904 | T10: =VLOOKUP(A10,Sheet2!$A$2:$R$3432,17,0) -> ME1G4219J0046776
A11: F0116-C3674 | B11: =VLOOKUP(A11,Sheet2!$A$2:$R$3432,2,0) -> 2025-01-16 19:58:04 | C11: - | D11: - | E11: =VLOOKUP(A11,Sheet2!$A$2:$R$3432,4,0) -> 8999016024 | F11: =VLOOKUP(A11,Sheet2!$A$2:$R$3432,3,0) -> TUSHAR RAUT | G11: - | H11: - | I11: - | J11: - | K11: =VLOOKUP(A11,Sheet2!$A$2:$R$3432,6,0) -> Yamaha FZ 25 | L11: - | M11: =VLOOKUP(A11,Sheet2!$A$2:$R$3432,5,0) -> MH16CW6540 | N11: - | O11: - | P11: - | Q11: - | R11: - | S11: =VLOOKUP(A11,Sheet2!$A$2:$R$3432,18,0) -> G3P1E0009245 | T11: =VLOOKUP(A11,Sheet2!$A$2:$R$3432,17,0) -> ME1RG6916M00005498
A12: F0116-C3679 | B12: =VLOOKUP(A12,Sheet2!$A$2:$R$3432,2,0) -> 2025-01-16 19:55:46 | C12: - | D12: - | E12: =VLOOKUP(A12,Sheet2!$A$2:$R$3432,4,0) -> 8237987263 | F12: =VLOOKUP(A12,Sheet2!$A$2:$R$3432,3,0) -> Jaideep | G12: - | H12: - | I12: - | J12: - | K12: =VLOOKUP(A12,Sheet2!$A$2:$R$3432,6,0) -> Hero Deluxe HF | L12: - | M12: =VLOOKUP(A12,Sheet2!$A$2:$R$3432,5,0) -> MH16CB4601 | N12: - | O12: - | P12: - | Q12: - | R12: - | S12: =VLOOKUP(A12,Sheet2!$A$2:$R$3432,18,0) | T12: =VLOOKUP(A12,Sheet2!$A$2:$R$3432,17,0)
A13: F0116-C3681 | B13: =VLOOKUP(A13,Sheet2!$A$2:$R$3432,2,0) -> 2025-01-16 19:43:47 | C13: - | D13: - | E13: =VLOOKUP(A13,Sheet2!$A$2:$R$3432,4,0) -> 9930836131 | F13: =VLOOKUP(A13,Sheet2!$A$2:$R$3432,3,0) -> Mithesh shroff | G13: - | H13: - | I13: - | J13: - | K13: =VLOOKUP(A13,Sheet2!$A$2:$R$3432,6,0) -> Suzuki Access 125 | L13: - | M13: =VLOOKUP(A13,Sheet2!$A$2:$R$3432,5,0) -> MH12HM6830 | N13: - | O13: - | P13: - | Q13: - | R13: - | S13: =VLOOKUP(A13,Sheet2!$A$2:$R$3432,18,0) | T13: =VLOOKUP(A13,Sheet2!$A$2:$R$3432,17,0)
... A3432: F0726-C5471 | B3432: =VLOOKUP(A3432,Sheet2!$A$2:$R$3432,2,0) -> 2025-07-26 20:31:42 | C3432: - | D3432: - | E3432: =VLOOKUP(A3432,Sheet2!$A$2:$R$3432,4,0) -> 9766589338 | F3432: =VLOOKUP(A3432,Sheet2!$A$2:$R$3432,3,0) -> Prathamesh Nikam | G3432: - | H3432: - | I3432: - | J3432: - | K3432: =VLOOKUP(A3432,Sheet2!$A$2:$R$3432,6,0) -> TVS Jupiter | L3432: - | M3432: =VLOOKUP(A3432,Sheet2!$A$2:$R$3432,5,0) -> MH12NH1362 | N3432: - | O3432: - | P3432: - | Q3432: - | R3432: - | S3432: =VLOOKUP(A3432,Sheet2!$A$2:$R$3432,18,0) | T3432: =VLOOKUP(A3432,Sheet2!$A$2:$R$3432,17,0)

Sheet Sheet2
A1: Jobcard Number | B1: Date | C1: Customer Name | D1: Mobile Number | E1: Vehicle Number | F1: Vehicle Details | G1: KM | H1: Discount | I1: Balance | J1: Received | K1: Total | L1: Final | M1: Spare Total | N1: Lube Total | O1: Job Total | P1: Payment Method | Q1: Chassis Number | R1: Engine Number
A2: F0116-C3678 | B2: 2025-01-16 19:45:21 | C2: Avinash Jadhav | D2: 7887425646 | E2: MH28AD2026 | F2: Yamaha Gladiator G5 | G2: 06043 | H2: 0 ₹ | I2: 0 | J2: 2863 | K2: 2863 | L2: 2863 | M2: 1580 | N2: 659 | O2: 624 | P2: UPI | Q2: ME1358044C2046624 | R2: 35B404594
A3: F0116-C3672 | B3: 2025-01-16 19:53:58 | C3: MANOJ CHAUDHARI | D3: 9049536462 | E3: MH12TW0951 | F3: Honda Activa 125 | G3: 27296 | H3: 0 ₹ | I3: 0 | J3: 1534 | K3: 1534 | L3: 1534 | M3: 355 | N3: 730 | O3: 449 | P3: UPI | Q3: ME4JK133LMG001221 | R3: JK13EG1004280
A4: F0116-C3680 | B4: 2025-01-16 19:56:55 | C4: AMOL CHITTE | D4: 9762184184 | E4: MH28AF8597 | F4: Yamaha FZ 1 | G4: 01 | H4: 0 ₹ | I4: 0 | J4: 1600 | K4: 1600 | L4: 1600 | M4: 1600 | N4: 0 | O4: 0 | P4: UPI
A5: F0113-C3659 | B5: 2025-01-16 19:59:01 | C5: Manoj | D5: 9049536462 | E5: MH14GB8855 | F5: Honda Activa | G5: 10344 | H5: 0 ₹ | I5: 0 | J5: 2887 | K5: 2887 | L5: 2887 | M5: 1633 | N5: 730 | O5: 524 | P5: UPI | Q5: ME4JF507BHU017099 | R5: JF50U3017142
A6: F0115-C3666 | B6: 2025-01-16 19:58:37 | C6: Manoj | D6: 9049536462 | E6: MH14ES3499 | F6: Honda Activa | G6: 54202 | H6: 0 ₹ | I6: 0 | J6: 1614 | K6: 1614 | L6: 1614 | M6: 360 | N6: 730 | O6: 524 | P6: UPI | Q6: ME4JF502LE8313692
A7: F0116-C3675 | B7: 2025-01-16 20:37:46 | C7: Archana Shingare | D7: 9146437954 | E7: MH14GV7627 | F7: TVS Scooty PEP Plus | G7: 29803 | H7: 064 ₹ | I7: 0 | J7: 1300 | K7: 1364 | L7: 1300 | M7: 185 | N7: 730 | O7: 449 | P7: UPI | Q7: MD626FG38J2AG0938 | R7: AG3AJ2937060
A8: F0116-C3682 | B8: 2025-01-16 20:36:29 | C8: VIPUL GUNJAL | D8: 9503093379 | E8: MH14BV6616 | F8: TVS Scooty PEP | G8: 19290 | H8: 0 ₹ | I8: 0 | J8: 4831 | K8: 4831 | L8: 4831 | M8: 901 | N8: 460 | O8: 3470 | P8: Cash
A9: E1129-C3202 | B9: 2024-11-30 10:40:50 | C9: Aditya Gupta | D9: 9881100507 | E9: MH14CV3016 | F9: Honda Activa 110 | G9: 12432 | H9: 0 ₹ | I9: 0 | J9: 1861 | K9: 1861 | L9: 1861 | M9: 618 | N9: 719 | O9: 524 | P9: UPI | Q9: ME4JC448EE823812 | R9: JC44E1349771
A10: E1127-C3183 | B10: 2024-11-30 10:48:50 | C10: Pratik | D10: 7410515046 | E10: MH12TG8914 | F10: KTM Duke 200 | G10: 9145 | H10: 0 ₹ | I10: 0 | J10: 1856 | K10: 1856 | L10: 1856 | M10: 1029 | N10: 128 | O10: 699 | P10: UPI
A11: E1129-C3199 | B11: 2024-11-30 10:39:26 | C11: Gaurang | D11: 9657702581 | E11: MH14CR5954 | F11: Bajaj Discover No Data | G11: 62363 | H11: 0 ₹ | I11: 0 | J11: 1643 | K11: 1643 | L11: 1643 | M11: 410 | N11: 784 | O11: 449 | P11: Cash | Q11: MDZDSJZZZTWK58252 | R11: MZMBTJ66869
A12: E1129-C3201 | B12: 2024-11-30 10:46:56 | C12: Suhas | D12: 8483833982 | E12: MH17BE1314 | F12: Honda Dio | G12: 41479 | H12: 0 ₹ | I12: 0 | J12: 1743 | K12: 1743 | L12: 1743 | M12: 420 | N12: 719 | O12: 604 | P12: Card | Q12: MEGJF392JE211927 | R12: JF39E70211907
A13: E1129-C3200 | B13: 2024-11-30 10:43:27 | C13: Himanshu Chothe | D13: 8237320223 | E13: MH12TW3707 | F13: Honda Activa 6G | G13: 13562 | H13: 0 ₹ | I13: 0 | J13: 1214 | K13: 1214 | L13: 1214 | M13: 120 | N13: 645 | O13: 449 | P13: UPI | Q13: ME4JF918LMG087052 | R13: JF91EG508758
A14: E1129-C3203 | B14: 2024-11-30 10:44:32 | C14: Rahil Shaikh | D14: 7507365078 | E14: MH15JE1843 | F14: Hero Xpulse 200 | G14: 21362 | H14: 0 ₹ | I14: 0 | J14: 629 | K14: 629 | L14: 629 | M14: 80 | N14: 0 | O14: 549 | P14: UPI | Q14: MC20AHMGKB1000 | R14: MBLDL061NGK2237
A15: E1220-C3415 | B15: 2024-12-20 20:33:38 | C15: Paresh Patil | D15: 7218664927 | E15: MH12KR6021 | F15: Hero Passion Pro | G15: 9577 | H15: 0 ₹ | I15: 0 | J15: 1511 | K15: 1511 | L15: 1511 | M15: 572 | N15: 190 | O15: 749 | P15: UPI
A16: E1129-C3196 | B16: 2024-11-30 10:51:51 | C16: Saurabh Nagarkar | D16: 9657081177 | E16: MH14HN0727 | F16: Bajaj Pulsar 220F | G16: 46530 | H16: 0 ₹ | I16: 0 | J16: 2309 | K16: 2309 | L16: 2309 | M16: 473 | N16: 962 | O16: 874 | P16: UPI | Q16: MD2A13EY3KLC10429 | R16: DK4CK1L01168
A17: E1129-C3205 | B17: 2024-11-30 10:38:13 | C17: Raj | D17: 8982156364 | E17: MH12TP0950 | F17: TVS Apache 160 4V | G17: 23304 | H17: 0 ₹ | I17: 0 | J17: 840 | K17: 840 | L17: 840 | M17: 391 | N17: 0 | O17: 449 | P17: Cash | Q17: MD637DE50M2D01233 | R17: GE5DM2X01136
A18: E1129-C3197 | B18: 2024-11-30 10:47:56 | C18: Renuka Patel | D18: 8888520035 | E18: MH27DC6939 | F18: Honda Activa 6G | G18: 6294 | H18: 0 ₹ | I18: 0 | J18: 1349 | K18: 1349 | L18: 1349 | M18: 255 | N18: 645 | O18: 449 | P18: UPI | Q18: ME4JF918KMW053320 | R18: JF91EW5053371
A19: E1127-C3185 | B19: 2024-11-30 10:55:00 | C19: Kumar | D19: 9673530315 | E19: MH12MJ9674 | F19: Honda Activa 3G | G19: 28651 | H19: 0 ₹ | I19: 0 | J19: 1591 | K19: 1591 | L19: 1591 | M19: 410 | N19: 657 | O19: 524 | P19: UPI
A20: E1127-C3182 | B20: 2024-11-30 10:56:48 | C20: Akshay | D20: 8484088353 | E20: MH14GK4333 | F20: Honda Activa 4G | G20: 40639 | H20: 0 ₹ | I20: 0 | J20: 2045 | K20: 2045 | L20: 2045 | M20: 791 | N20: 730 | O20: 524 | P20: UPI | Q20: ME4JF507GHU424715 | R20: JF50EU5424616
A21: E1129-C3198 | B21: 2024-11-30 10:47:20 | C21: Sujay Joshi | D21: 9890675383 | E21: MH12QQ8618 | F21: Suzuki Access 125 | G21: 2358 | H21: 0 ₹ | I21: 0 | J21: 1200 | K21: 1200 | L21: 1200 | M21: 1150 | N21: 0 | O21: 50 | P21: UPI | Q21: MB8DP11AFJ8925232 | R21: AF211722746
A22: E1128-C3190 | B22: 2024-11-30 11:27:00 | C22: Somesh More | D22: 7588710115 | E22: MH17BF7914 | F22: TVS Jupiter | G22: 26917 | H22: 0 ₹ | I22: 0 | J22: 1960 | K22: 1960 | L22: 1960 | M22: 781 | N22: 730 | O22: 449 | P22: UPI | Q22: MD626BG41E1N65539 | R22: BG4NE1359276
A23: E1128-C3195 | B23: 2024-11-30 10:58:28 | C23: SHAILESH KHANDAGALE | D23: 7840978199 | E23: MH45AG5687 | F23: Honda Shine | G23: 38384 | H23: 0 ₹ | I23: 0 | J23: 1589 | K23: 1589 | L23: 1589 | M23: 356 | N23: 784 | O23: 449 | P23: UPI | Q23: ME4JC654EH7087173 | R23: JC65E71127864
A24: E1127-C3187 | B24: 2024-11-30 10:52:58 | C24: KISHOR CHAURE | D24: 9767809683 | E24: MH14GF9795 | F24: Honda Activa 4G | G24: 33544 | H24: 0 ₹ | I24: 0 | J24: 1564 | K24: 1564 | L24: 1564 | M24: 310 | N24: 730 | O24: 524 | P24: UPI | Q24: ME4JF5070H4123771 | R24: JF50E451239332
A25: E1128-C3192 | B25: 2024-11-30 11:28:09 | C25: CHINMAY | D25: 8237668546 | E25: MH20FF0016 | F25: Bajaj Pulsar 200 RS | G25: 37680 | H25: 0 ₹ | I25: 0 | J25: 1926 | K25: 1926 | L25: 1926 | M25: 1301 | N25: 0 | O25: 625 | P25: UPI | R25: JLYCK246904
A26: E1128-C3191 | B26: 2024-11-30 11:23:05 | C26: Atul Kad | D26: 8149471510 | E26: MH21BJ2493 | F26: Suzuki Intruder 150 | G26: 25910 | H26: 0 ₹ | I26: 0 | J26: 1671 | K26: 1671 | L26: 1671 | M26: 288 | N26: 784 | O26: 599 | P26: UPI | Q26: 8105090 | R26: 473507
A27: E1128-C3193 | B27: 2024-11-30 11:31:02 | C27: Girish Kinikar | D27: 9579717727 | E27: MH19CD1462 | F27: Honda Activa 3G | G27: 10999 | H27: 0 ₹ | I27: 0 | J27: 1454 | K27: 1454 | L27: 1454 | M27: 200 | N27: 730 | O27: 524 | P27: Cash | Q27: ME4JF504EFT349427 | R27: JF50ET2350274
A28: E1128-C3189 | B28: 2024-11-30 11:29:32 | C28: Sunny | D28: 9607926002 | E28: MH12HU5357 | F28: TVS Scooty PEP Plus | G28: 28773 | H28: 0 ₹ | I28: 0 | J28: 1609 | K28: 1609 | L28: 1609 | M28: 430 | N28: 730 | O28: 449 | P28: UPI | Q28: MD626BG39B2N18935 | R28: 2633859
A29: E1106-C2987 | B29: 2024-11-30 11:32:56 | C29: ADITYA SINHG | D29: 9172523743 | E29: MH11AA9796 | F29: Bajaj Pulsar 150 | G29: 23359 | H29: 0 ₹ | I29: 0 | J29: 2303 | K29: 2303 | L29: 2303 | M29: 2028 | N29: 0 | O29: 275 | P29: UPI
A30: E1130-C3208 | B30: 2024-11-30 20:17:57 | C30: Rohit | D30: 7620002519 | E30: MH22AY9183 | F30: Honda Shine SP | G30: 19716 | H30: 0 ₹ | I30: 0 | J30: 1399 | K30: 1399 | L30: 1399 | M30: 166 | N30: 784 | O30: 449 | P30: UPI | Q30: ME4JC83EHNG077818 | R30: JC83EG3234540
A31: E1220-C3410 | B31: 2024-12-20 20:36:30 | C31: Santosh Bhalerao | D31: 8275204492 | E31: MH12BU7746 | F31: Hero Splendor | G31: 11804 | H31: 0 ₹ | I31: 0 | J31: 4552 | K31: 4552 | L31: 4552 | M31: 3188 | N31: 190 | O31: 1174 | P31: UPI
A32: E1130-C3210 | B32: 2024-11-30 20:07:02 | C32: RAM NARESH | D32: 9175645184 | E32: MH12QP5582 | F32: TVS Victor | G32: 109897 | H32: 0 ₹ | I32: 0 | J32: 1374 | K32: 1374 | L32: 1374 | M32: 435 | N32: 190 | O32: 749 | P32: UPI | Q32: MD625GF11J1E23809 | R32: LE1EJ1714914
A33: E1220-C3411 | B33: 2024-12-20 20:32:13 | C33: Amit Salve | D33: 8261925966 | E33: MH12LS2093 | F33: Yamaha FZ | G33: 01 | H33: 0 ₹ | I33: 0 | J33: 7261 | K33: 7261 | L33: 7261 | M33: 4897 | N33: 900 | O33: 1464 | P33: UPI
A34: F0213-C3953 | B34: 2025-02-13 18:48:41 | C34: RAHUL GAIKWAD | D34: 9923763880 | E34: MH10BD1460 | F34: Honda Shine CB | G34: 33269 | H34: 0 ₹ | I34: 0 | J34: 3033 | K34: 3033 | L34: 3033 | M34: 1675 | N34: 784 | O34: 574 | P34: UPI
A35: E1130-C3218 | B35: 2024-11-30 20:15:51 | C35: LAXMIKANT | D35: 8668610879 | E35: MH16BS1559 | F35: Honda Activa 3G | G35: 43737 | H35: 0 ₹ | I35: 0 | J35: 695 | K35: 695 | L35: 695 | M35: 650 | N35: 0 | O35: 45 | P35: UPI | Q35: ME4JF50544TG430642 | R35: JF50ET3630768
A36: E1220-C3413 | B36: 2024-12-20 20:35:18 | C36: Dheeraj | D36: 7030469122 | E36: MH04KZ2927 | F36: Suzuki Gixxer SF | G36: 29937 | H36: 0 ₹ | I36: 0 | J36: 1708 | K36: 1708 | L36: 1708 | M36: 325 | N36: 784 | O36: 599 | P36: UPI
A37: E1220-C3416 | B37: 2024-12-20 17:12:04 | C37: Omkar Shirke | D37: 9923220239 | E37: MH12KD2649 | F37: TVS Wego Basic | G37: 39999 | H37: 0 ₹ | I37: 0 | J37: 2166 | K37: 2166 | L37: 2166 | M37: 2166 | N37: 0 | O37: 0 | P37: UPI | Q37: MD626AG46D1643177
A38: E1220-C3407 | B38: 2024-12-20 20:34:01 | C38: Rupesh | D38: 9762574209 | E38: MH20GR0562 | F38: Honda Activa 6G | G38: 5831 | H38: 0 ₹ | I38: 0 | J38: 1174 | K38: 1174 | L38: 1174 | M38: 80 | N38: 645 | O38: 449 | P38: UPI
A39: E1130-C3211 | B39: 2024-11-30 19:57:50 | C39: Venkatesh Kulkarni | D39: 9168712211 | E39: MH12JJ6470 | F39: Bajaj Avenger 220 Street | G39: 04974 | H39: 0 ₹ | I39: 0 | J39: 2198 | K39: 2198 | L39: 2198 | M39: 701 | N39: 898 | O39: 599 | P39: UPI | Q39: MDZAZEZOCCG12121 | R39: PDZCC0115556
A40: E1220-C3408 | B40: 2024-12-20 20:34:31 | C40: SANKALP YERAWAR | D40: 8237669414 | E40: MH14HP1653 | F40: Yamaha MT 15 | G40: 20305 | H40: 0 ₹ | I40: 0 | J40: 3233 | K40: 3233 | L40: 3233 | M40: 1525 | N40: 784 | O40: 924 | P40: UPI | Q40: ME1RG5913K0003326 | R40: G3K5E0086860
...
